<?xml version="1.0" ?>
<!-- =================================================================================== -->
<!-- |    This document was autogenerated by xacro from ./src/anymal_bear/anymal_bear_description/urdf/anymal.urdf.xacro | -->
<!-- |    EDITING THIS FILE BY HAND IS NOT RECOMMENDED                                 | -->
<!-- =================================================================================== -->
<!-- This file contains the description of the ANYmal Bedi robot. -->
<robot name="anymal" xmlns:xacro="http://www.ros.org/wiki/xacro">
    <material name="black">
        <color rgba="0.0 0.0 0.0 1.0"/>
    </material>
    <material name="blue">
        <color rgba="0.0 0.0 0.8 1.0"/>
    </material>
    <material name="green">
        <color rgba="0.0 0.8 0.0 1.0"/>
    </material>
    <material name="grey">
        <color rgba="0.2 0.2 0.2 1.0"/>
    </material>
    <material name="light_grey">
        <color rgba="0.4 0.4 0.4 1.0"/>
    </material>
    <material name="orange">
        <color rgba="1.0 0.423529411765 0.0392156862745 1.0"/>
    </material>
    <material name="brown">
        <color rgba="0.870588235294 0.811764705882 0.764705882353 1.0"/>
    </material>
    <material name="red">
        <color rgba="0.8 0.0 0.0 1.0"/>
    </material>
    <material name="white">
        <color rgba="1.0 1.0 1.0 1.0"/>
    </material>
    <material name="anymal_material">
        <color rgba="0.4 0.4 0.4 1.0"/>
    </material>
    <!-- Xacro:Properties -->
    <!-- [m] -->
    <!-- Base link -->
    <link name="base">
        <visual>
            <origin rpy="0 0 0" xyz="0 0 0"/>
            <geometry>
                <mesh filename="anymal_base.dae" scale="0.001 0.001     0.001"/>
            </geometry>
            <material name="anymal_material"/>
        </visual>

        <collision>
            <!-- Main Body -->
            <origin rpy="0 0 0" xyz="0 0 0.08"/>
            <geometry>
                <box size="0.529 0.22 0.24"/>
            </geometry>
        </collision>

        <collision>
            <!-- Upper Handle -->
            <origin rpy="0 0 0" xyz="0 0 0.23"/>
            <geometry>
                <box size="0.51 0.10 0.14"/>
            </geometry>
        </collision>

        <collision>
            <!-- Front Handle -->
            <origin rpy="0 0 0" xyz="0.34 0 0.18"/>
            <geometry>
                <box size="0.18 0.20 0.1"/>
            </geometry>
        </collision>


        <collision>
            <!-- Belly plate bottom bump-->
            <origin rpy="0 0 0" xyz="0 0 -0.04"/>
            <geometry>
                <box size="0.531 0.15 0.085"/>
            </geometry>
        </collision>

        <collision>
            <!-- Belly plate middle bump-->
            <origin rpy="0 0 0" xyz="0 0 -0.04"/>
            <geometry>
                <box size="0.531 0.1 0.17"/>
            </geometry>
        </collision>

    </link>
    <!-- Fixed joint to add dummy inertia link -->
    <joint name="base_to_base_inertia" type="fixed">
        <parent link="base"/>
        <child link="base_inertia"/>
        <origin rpy="0 0 0" xyz="0 0 0"/>
    </joint>
    <!-- Dummy inertia link, because KDL cannot have inertia on the base link -->
    <link name="base_inertia">
        <inertial>
            <origin rpy="0 0 0" xyz="-0.001712029101 -0.001380403461 0.053974184671"/>
            <mass value="16.0"/>
            <inertia ixx="0.248057547487" ixy="0.00109783880089" ixz="-0.00394501164854" iyy="0.650151658461"
                     iyz="-0.00213569105487" izz="0.620944203624"/>
        </inertial>
    </link>
    <!-- Xacro:Properties -->
    <!-- [kg * m^2] -->
    <!-- [Nm] -->
    <link name="LF_HIP">
        <visual>
            <origin rpy="0 1.5707963268 0" xyz="0 0 0"/>
            <geometry>
                <mesh filename="anymal_hip.dae" scale="0.001 0.001 0.001"/>
            </geometry>
            <material name="white"/>
        </visual>

        <collision>
            <!-- Actuator -->
            <origin rpy="1.57079632679 0 0" xyz="0.0735 -0.00905 0.0"/>
            <geometry>
                <cylinder length="0.09" radius="0.05"/>
            </geometry>
        </collision>

        <collision>
            <!-- Protector -->
            <origin rpy="1.57079632679 0 0" xyz="0.0735 -0.00905 0.0"/>
            <geometry>
                <cylinder length="0.04" radius="0.06"/>
            </geometry>
        </collision>

        <inertial>
            <origin rpy="0 0 0" xyz="0.062835805581 -0.004658817611 0.001702621241"/>
            <mass value="1.442092122"/>
            <inertia ixx="0.00177548706114" ixy="1.1580067729e-05" ixz="-9.044459477e-06" iyy="0.00170137645039"
                     iyz="-5.8492762287e-05" izz="0.00196063669653"/>
        </inertial>
    </link>
    <!-- Hip joint -->
    <joint name="LF_HAA" type="revolute">
        <parent link="base"/>
        <child link="LF_HIP"/>
        <origin xyz="0.277 0.116 0.0"/>
        <axis xyz="1 0 0"/>
        <dynamics damping="0.0" friction="0.0"/>
    </joint>
    <!-- Xacro:Properties -->
    <!-- [m] -->
    <!-- [Nm] -->
    <link name="LF_THIGH">
        <visual>
            <origin rpy="0 0 0.0" xyz="0 0 0"/>
            <geometry>
                <mesh filename="anymal_thigh.dae" scale="0.001 0.001     0.001"/>
            </geometry>
            <material name="anymal_material"/>
        </visual>

        <collision>
            <!-- upper protector -->
            <origin rpy="1.57079632679 0 0" xyz="0.0 0.0325 0"/>
            <geometry>
                <cylinder length="0.06" radius="0.04"/>
            </geometry>
        </collision>

        <collision>
            <!-- upper protector -->
            <origin rpy="1.57079632679 0 0" xyz="0.0 0.0175 0"/>
            <geometry>
                <cylinder length="0.045" radius="0.065"/>
            </geometry>
        </collision>

        <collision>
            <!-- thigh with heat fins -->
            <origin rpy="0.145 0 0" xyz="0 0.035 -0.125"/>
            <geometry>
                <box size="0.06 0.035 0.18"/>
            </geometry>
        </collision>

        <collision>
            <!-- KFE actuator -->
            <origin rpy="1.57079632679 0 0" xyz="0.0 0.069 -0.25"/>
            <geometry>
                <cylinder length="0.11" radius="0.06"/>
            </geometry>
        </collision>

        <inertial>
            <origin rpy="0 0 0" xyz="-0.000224951525 0.05480248145 -0.209489045173"/>
            <mass value="1.69884373"/>
            <inertia ixx="0.0131442404046" ixy="-2.44232829e-07" ixz="2.3986036365e-05" iyy="0.0127576740658"
                     iyz="-0.00158639883939" izz="0.00209114731186"/>
        </inertial>
    </link>
    <!-- Thigh joint -->
    <joint name="LF_HFE" type="revolute">
        <parent link="LF_HIP"/>
        <child link="LF_THIGH"/>
        <origin xyz="0.0635                    0.04095                    0.0"/>
        <axis xyz="0 1 0"/>
        <dynamics damping="0.0" friction="0.0"/>
    </joint>
    <!-- Xacro:Properties -->
    <!-- [m] -->
    <!-- [Nm] -->
    <link name="LF_SHANK">
        <visual>
            <origin rpy="0 0 0.0" xyz="0 0 0"/>
            <geometry>
                <mesh filename="anymal_shank_l.dae" scale="0.001 0.001     0.001"/>
            </geometry>
            <material name="anymal_material"/>
        </visual>
        <inertial>
            <origin rpy="0 0 0" xyz="0.029 -0.004 0.001"/>
            <mass value="0.21"/>
            <inertia ixx="0.0037693717909" ixy="-7.7334500762e-05" ixz="-0.000152069372983" iyy="0.00400446467635"
                     iyz="-0.0003218356083" izz="0.000418471691904"/>
        </inertial>

    </link>
    <!-- Shank joint -->
    <joint name="LF_KFE" type="revolute">
        <parent link="LF_THIGH"/>
        <child link="LF_SHANK"/>
        <origin xyz="0.0 0.109 -0.25"/>
        <axis xyz="0 1 0"/>
        <dynamics damping="0.0" friction="0.0"/>
    </joint>
    <!-- Xacro:Properties -->
    <!-- [m] -->
    <!-- Shank to Adapter joint -->
    <joint name="LF_SHANK_TO_ADAPTER" type="fixed">
        <parent link="LF_SHANK"/>
        <child link="LF_ADAPTER"/>
        <origin rpy="0.0 0.0 0.0" xyz="0.1 -0.02 0.0"/>
    </joint>
    <!-- Adapter link -->
    <link name="LF_ADAPTER">
        <visual>
            <origin rpy="0 0 0.0" xyz="0 0 -0.0325"/>
            <geometry>
                <mesh filename="anymal_adapter.dae" scale="0.001 0.001     0.001"/>
            </geometry>
            <material name="anymal_material"/>
        </visual>

        <collision>
            <origin rpy="0 0 0" xyz="0 0 -0.0"/>
            <geometry>
                <box size="0.045 0.045 0.065"/>
            </geometry>
            <material name="anymal_material"/>
        </collision>

        <collision>
            <origin rpy="0 0 0" xyz="0 0 -0.145"/>
            <geometry>
                <cylinder length="0.26" radius="0.015"/>
            </geometry>
            <material name="anymal_material"/>
        </collision>

    </link>
    <!-- Adapter to Foot joint -->
    <joint name="LF_ADAPTER_TO_FOOT" type="fixed">
        <parent link="LF_ADAPTER"/>
        <child link="LF_FOOT"/>
        <origin rpy="0.0 0.0 0.0" xyz="0.0 0.0 -0.28625"/>
    </joint>
    <!-- Foot link -->
    <link name="LF_FOOT">
        <visual>
            <origin xyz="0 0 0.03"/>
            <geometry>
                <mesh filename="anymal_bota.dae" scale="0.001 0.001     0.001"/>
            </geometry>
        </visual>
        <collision>
            <origin xyz="0 0 0.0"/>
            <geometry>
                <sphere radius="0.032"/>
            </geometry>
        </collision>
    </link>
    <!-- Gazebo customization -->
    <gazebo reference="LF_FOOT">
        <kp>1000000.0</kp>
        <kd>100.0</kd>
        <mu1>0.8</mu1>
        <mu2>0.8</mu2>
    </gazebo>
    <!-- Xacro:Properties -->
    <!-- [kg * m^2] -->
    <!-- [Nm] -->
    <link name="RF_HIP">
        <visual>
            <origin rpy="3.14159265359 -1.5707963268 0" xyz="0 0 0"/>
            <geometry>
                <mesh filename="anymal_hip.dae" scale="0.001 0.001     0.001"/>
            </geometry>
            <material name="white"/>
        </visual>

        <collision>
            <!-- Actuator -->
            <origin rpy="1.57079632679 0 0" xyz="0.0735 0.00905 0.0"/>
            <geometry>
                <cylinder length="0.09" radius="0.05"/>
            </geometry>
        </collision>

        <collision>
            <!-- Protector -->
            <origin rpy="1.57079632679 0 0" xyz="0.0735 0.00905 0.0"/>
            <geometry>
                <cylinder length="0.04" radius="0.06"/>
            </geometry>
        </collision>

        <inertial>
            <origin rpy="0 0 0" xyz="0.062835805581 0.004658817611 0.001702621241"/>
            <mass value="1.442092122"/>
            <inertia ixx="0.00177548706114" ixy="-1.1580067729e-05" ixz="-9.044459477e-06" iyy="0.00170137645039"
                     iyz="5.8492762287e-05" izz="0.00196063669653"/>
        </inertial>
    </link>
    <!-- Hip joint -->
    <joint name="RF_HAA" type="revolute">
        <parent link="base"/>
        <child link="RF_HIP"/>
        <origin xyz="0.277 -0.116 0.0"/>
        <axis xyz="1 0 0"/>
        <dynamics damping="0.0" friction="0.0"/>
    </joint>
    <!-- Xacro:Properties -->
    <!-- [m] -->
    <!-- [Nm] -->
    <link name="RF_THIGH">
        <visual>
            <origin rpy="3.14159265359 3.14159265359 0.0" xyz="0 0 0"/>
            <geometry>
                <mesh filename="anymal_thigh.dae" scale="0.001 0.001     0.001"/>
            </geometry>
            <material name="anymal_material"/>
        </visual>

        <collision>
            <!-- upper protector -->
            <origin rpy="1.57079632679 0 0" xyz="0.0 -0.0325 0"/>
            <geometry>
                <cylinder length="0.06" radius="0.04"/>
            </geometry>
        </collision>

        <collision>
            <!-- upper protector -->
            <origin rpy="1.57079632679 0 0" xyz="0.0 -0.0175 0"/>
            <geometry>
                <cylinder length="0.045" radius="0.065"/>
            </geometry>
        </collision>

        <collision>
            <!-- thigh with heat fins -->
            <origin rpy="-0.145 0 0" xyz="0 -0.035 -0.125"/>
            <geometry>
                <box size="0.06 0.035 0.18"/>
            </geometry>
        </collision>

        <collision>
            <!-- KFE actuator -->
            <origin rpy="1.57079632679 0 0" xyz="0.0 -0.069 -0.25"/>
            <geometry>
                <cylinder length="0.11" radius="0.06"/>
            </geometry>
        </collision>

        <inertial>
            <origin rpy="0 0 0" xyz="-0.000224951525 -0.05480248145 -0.209489045173"/>
            <mass value="1.69884373"/>
            <inertia ixx="0.0131442404046" ixy="2.44232829e-07" ixz="2.3986036365e-05" iyy="0.0127576740658"
                     iyz="0.00158639883939" izz="0.00209114731186"/>
        </inertial>
    </link>
    <!-- Thigh joint -->
    <joint name="RF_HFE" type="revolute">
        <parent link="RF_HIP"/>
        <child link="RF_THIGH"/>
        <origin xyz="0.0635                    -0.04095                    0.0"/>
        <axis xyz="0 1 0"/>
        <dynamics damping="0.0" friction="0.0"/>
    </joint>
    <!-- Xacro:Properties -->
    <!-- [m] -->
    <!-- [Nm] -->
    <link name="RF_SHANK">
        <visual>
            <origin rpy="0 0 0.0" xyz="0 0 0"/>
            <geometry>
                <mesh filename="anymal_shank_r.dae" scale="0.001 0.001     0.001"/>
            </geometry>
            <material name="anymal_material"/>
        </visual>

        <inertial>
            <origin rpy="0 0 0" xyz="0.029 0.004 0.001"/>
            <mass value="0.21"/>
            <inertia ixx="0.0037693717909" ixy="7.7334500762e-05" ixz="-0.000152069372983" iyy="0.00400446467635"
                     iyz="0.0003218356083" izz="0.000418471691904"/>
        </inertial>
    </link>
    <!-- Shank joint -->
    <joint name="RF_KFE" type="revolute">
        <parent link="RF_THIGH"/>
        <child link="RF_SHANK"/>
        <origin xyz="0.0 -0.109 -0.25"/>
        <axis xyz="0 1 0"/>
        <dynamics damping="0.0" friction="0.0"/>
    </joint>
    <!-- Xacro:Properties -->
    <!-- [m] -->
    <!-- Shank to Adapter joint -->
    <joint name="RF_SHANK_TO_ADAPTER" type="fixed">
        <parent link="RF_SHANK"/>
        <child link="RF_ADAPTER"/>
        <origin rpy="-0.0 0.0 -0.0" xyz="0.1 0.02 0.0"/>
    </joint>
    <!-- Adapter link -->
    <link name="RF_ADAPTER">
        <visual>
            <origin rpy="0 0 0.0" xyz="0 0 -0.0325"/>
            <geometry>
                <mesh filename="anymal_adapter.dae" scale="0.001 0.001     0.001"/>
            </geometry>
            <material name="anymal_material"/>
        </visual>

        <collision>
            <origin rpy="0 0 0" xyz="0 0 -0.0"/>
            <geometry>
                <box size="0.045 0.045 0.065"/>
            </geometry>
            <material name="anymal_material"/>
        </collision>

        <collision>
            <origin rpy="0 0 0" xyz="0 0 -0.145"/>
            <geometry>
                <cylinder length="0.26" radius="0.015"/>
            </geometry>
            <material name="anymal_material"/>
        </collision>


    </link>
    <!-- Adapter to Foot joint -->
    <joint name="RF_ADAPTER_TO_FOOT" type="fixed">
        <parent link="RF_ADAPTER"/>
        <child link="RF_FOOT"/>
        <origin rpy="0.0 0.0 0.0" xyz="0.0 -0.0 -0.28625"/>
    </joint>
    <!-- Foot link -->
    <link name="RF_FOOT">
        <visual>
            <origin xyz="0 0 0.03"/>
            <geometry>
                <mesh filename="anymal_bota.dae" scale="0.001 0.001     0.001"/>
            </geometry>
        </visual>
        <collision>
            <origin xyz="0 0 0"/>
            <geometry>
                <sphere radius="0.032"/>
            </geometry>
        </collision>
    </link>
    <!-- Gazebo customization -->
    <gazebo reference="RF_FOOT">
        <kp>1000000.0</kp>
        <kd>100.0</kd>
        <mu1>0.8</mu1>
        <mu2>0.8</mu2>
    </gazebo>
    <!-- Xacro:Properties -->
    <!-- [kg * m^2] -->
    <!-- [Nm] -->
    <link name="LH_HIP">
        <visual>
            <origin rpy="0 -1.5707963268 0" xyz="0 0 0"/>
            <geometry>
                <mesh filename="anymal_hip.dae" scale="0.001 0.001     0.001"/>
            </geometry>
            <material name="white"/>
        </visual>

        <collision>
            <!-- Actuator -->
            <origin rpy="-1.57079632679 0 0" xyz="-0.0735 -0.00905 0.0"/>
            <geometry>
                <cylinder length="0.09" radius="0.05"/>
            </geometry>
        </collision>

        <collision>
            <!-- Protector -->
            <origin rpy="-1.57079632679 0 0" xyz="-0.0735 -0.00905 0.0"/>
            <geometry>
                <cylinder length="0.04" radius="0.06"/>
            </geometry>
        </collision>

        <inertial>
            <origin rpy="0 0 0" xyz="-0.062835805581 -0.004658817611 0.001702621241"/>
            <mass value="1.442092122"/>
            <inertia ixx="0.00177548706114" ixy="-1.1580067729e-05" ixz="9.044459477e-06" iyy="0.00170137645039"
                     iyz="-5.8492762287e-05" izz="0.00196063669653"/>
        </inertial>
    </link>
    <!-- Hip joint -->
    <joint name="LH_HAA" type="revolute">
        <parent link="base"/>
        <child link="LH_HIP"/>
        <origin xyz="-0.277 0.116 0.0"/>
        <axis xyz="1 0 0"/>
        <dynamics damping="0.0" friction="0.0"/>
    </joint>
    <!-- Xacro:Properties -->
    <!-- [m] -->
    <!-- [Nm] -->
    <link name="LH_THIGH">
        <visual>
            <origin rpy="0 0 0" xyz="0 0 0"/>
            <geometry>
                <mesh filename="anymal_thigh.dae" scale="0.001 0.001     0.001"/>
            </geometry>
            <material name="anymal_material"/>
        </visual>

        <collision>
            <!-- upper protector -->
            <origin rpy="1.57079632679 0 0" xyz="-0.0 0.0325 0"/>
            <geometry>
                <cylinder length="0.06" radius="0.04"/>
            </geometry>
        </collision>

        <collision>
            <!-- upper protector -->
            <origin rpy="1.57079632679 0 0" xyz="0.0 0.0175 0"/>
            <geometry>
                <cylinder length="0.045" radius="0.065"/>
            </geometry>
        </collision>

        <collision>
            <!-- thigh with heat fins -->
            <origin rpy="0.145 0 0" xyz="0 0.035 -0.125"/>
            <geometry>
                <box size="0.06 0.035 0.18"/>
            </geometry>
        </collision>

        <collision>
            <!-- KFE actuator -->
            <origin rpy="1.57079632679 0 0" xyz="0.0 0.069 -0.25"/>
            <geometry>
                <cylinder length="0.11" radius="0.06"/>
            </geometry>
        </collision>

        <inertial>
            <origin rpy="0 0 0" xyz="0.000224951525 0.05480248145 -0.209489045173"/>
            <mass value="1.69884373"/>
            <inertia ixx="0.0131442404046" ixy="2.44232829e-07" ixz="-2.3986036365e-05" iyy="0.0127576740658"
                     iyz="-0.00158639883939" izz="0.00209114731186"/>
        </inertial>
    </link>
    <!-- Thigh joint -->
    <joint name="LH_HFE" type="revolute">
        <parent link="LH_HIP"/>
        <child link="LH_THIGH"/>
        <origin xyz="-0.0635                    0.04095                    0.0"/>
        <axis xyz="0 1 0"/>
        <dynamics damping="0.0" friction="0.0"/>
    </joint>
    <!-- Xacro:Properties -->
    <!-- [m] -->
    <!-- [Nm] -->
    <link name="LH_SHANK">
        <visual>
            <origin rpy="0 0 -3.14159265359" xyz="0 0 0"/>
            <geometry>
                <mesh filename="anymal_shank_r.dae" scale="0.001 0.001     0.001"/>
            </geometry>
            <material name="anymal_material"/>
        </visual>
        <inertial>
            <origin rpy="0 0 0" xyz="-0.029 -0.004 0.001"/>
            <mass value="0.21"/>
            <inertia ixx="0.0037693717909" ixy="7.7334500762e-05" ixz="0.000152069372983" iyy="0.00400446467635"
                     iyz="-0.0003218356083" izz="0.000418471691904"/>
        </inertial>
    </link>
    <!-- Shank joint -->
    <joint name="LH_KFE" type="revolute">
        <parent link="LH_THIGH"/>
        <child link="LH_SHANK"/>
        <origin xyz="-0.0 0.109 -0.25"/>
        <axis xyz="0 1 0"/>
        <dynamics damping="0.0" friction="0.0"/>
    </joint>
    <!-- Xacro:Properties -->
    <!-- [m] -->
    <!-- Shank to Adapter joint -->
    <joint name="LH_SHANK_TO_ADAPTER" type="fixed">
        <parent link="LH_SHANK"/>
        <child link="LH_ADAPTER"/>
        <origin rpy="0.0 -0.0 -0.0" xyz="-0.1 -0.02 0.0"/>
    </joint>
    <!-- Adapter link -->
    <link name="LH_ADAPTER">
        <visual>
            <origin rpy="0 0 0.0" xyz="0 0 -0.0325"/>
            <geometry>
                <mesh filename="anymal_adapter.dae" scale="0.001 0.001     0.001"/>
            </geometry>
            <material name="anymal_material"/>
        </visual>

        <collision>
            <origin rpy="0 0 0" xyz="0 0 -0.0"/>
            <geometry>
                <box size="0.045 0.045 0.065"/>
            </geometry>
            <material name="anymal_material"/>
        </collision>

        <collision>
            <origin rpy="0 0 0" xyz="0 0 -0.145"/>
            <geometry>
                <cylinder length="0.26" radius="0.015"/>
            </geometry>
            <material name="anymal_material"/>
        </collision>

    </link>
    <!-- Adapter to Foot joint -->
    <joint name="LH_ADAPTER_TO_FOOT" type="fixed">
        <parent link="LH_ADAPTER"/>
        <child link="LH_FOOT"/>
        <origin rpy="0.0 -0.0 -0.0" xyz="0.0 0.0 -0.28625"/>
    </joint>
    <!-- Foot link -->
    <link name="LH_FOOT">

        <visual>
            <origin xyz="0 0 0.03"/>
            <geometry>
                <mesh filename="anymal_bota.dae" scale="0.001 0.001     0.001"/>
            </geometry>
        </visual>
        <collision>
            <origin xyz="0 0 0"/>
            <geometry>
                <sphere radius="0.032"/>
            </geometry>
        </collision>
    </link>
    <!-- Gazebo customization -->
    <gazebo reference="LH_FOOT">
        <kp>1000000.0</kp>
        <kd>100.0</kd>
        <mu1>0.8</mu1>
        <mu2>0.8</mu2>
    </gazebo>
    <!-- Xacro:Properties -->
    <!-- [kg * m^2] -->
    <!-- [Nm] -->
    <link name="RH_HIP">
        <visual>
            <origin rpy="3.14159265359 1.5707963268 0" xyz="0 0 0"/>
            <geometry>
                <mesh filename="anymal_hip.dae" scale="0.001 0.001     0.001"/>
            </geometry>
            <material name="white"/>
        </visual>

        <collision>
            <!-- Actuator -->
            <origin rpy="1.57079632679 0 0" xyz="-0.0735 0.00905 0.0"/>
            <geometry>
                <cylinder length="0.09" radius="0.05"/>
            </geometry>
        </collision>

        <collision>
            <!-- Protector -->
            <origin rpy="1.57079632679 0 0" xyz="-0.0735 0.00905 0.0"/>
            <geometry>
                <cylinder length="0.04" radius="0.06"/>
            </geometry>
        </collision>

        <inertial>
            <origin rpy="0 0 0" xyz="-0.062835805581 0.004658817611 0.001702621241"/>
            <mass value="1.442092122"/>
            <inertia ixx="0.00177548706114" ixy="1.1580067729e-05" ixz="9.044459477e-06" iyy="0.00170137645039"
                     iyz="5.8492762287e-05" izz="0.00196063669653"/>
        </inertial>
    </link>
    <!-- Hip joint -->
    <joint name="RH_HAA" type="revolute">
        <parent link="base"/>
        <child link="RH_HIP"/>
        <origin xyz="-0.277 -0.116 0.0"/>
        <axis xyz="1 0 0"/>
        <dynamics damping="0.0" friction="0.0"/>
    </joint>
    <!-- Xacro:Properties -->
    <!-- [m] -->
    <!-- [Nm] -->
    <link name="RH_THIGH">
        <visual>
            <origin rpy="0 0 -3.14159265359" xyz="0 0 0"/>
            <geometry>
                <mesh filename="anymal_thigh.dae" scale="0.001 0.001     0.001"/>
            </geometry>
            <material name="anymal_material"/>
        </visual>

        <collision>
            <!-- upper protector -->
            <origin rpy="1.57079632679 0 0" xyz="-0.0 -0.0325 0"/>
            <geometry>
                <cylinder length="0.06" radius="0.04"/>
            </geometry>
        </collision>

        <collision>
            <!-- upper protector -->
            <origin rpy="1.57079632679 0 0" xyz="0.0 -0.0175 0"/>
            <geometry>
                <cylinder length="0.045" radius="0.065"/>
            </geometry>
        </collision>

        <collision>
            <!-- thigh with heat fins -->
            <origin rpy="-0.145 0 0" xyz="0 -0.035 -0.125"/>
            <geometry>
                <box size="0.06 0.035 0.18"/>
            </geometry>
        </collision>

        <collision>
            <!-- KFE actuator -->
            <origin rpy="1.57079632679 0 0" xyz="0.0 -0.069 -0.25"/>
            <geometry>
                <cylinder length="0.11" radius="0.06"/>
            </geometry>
        </collision>

        <inertial>
            <origin rpy="0 0 0" xyz="0.000224951525 -0.05480248145 -0.209489045173"/>
            <mass value="1.69884373"/>
            <inertia ixx="0.0131442404046" ixy="-2.44232829e-07" ixz="-2.3986036365e-05" iyy="0.0127576740658"
                     iyz="0.00158639883939" izz="0.00209114731186"/>
        </inertial>
    </link>
    <!-- Thigh joint -->
    <joint name="RH_HFE" type="revolute">
        <parent link="RH_HIP"/>
        <child link="RH_THIGH"/>
        <origin xyz="-0.0635                    -0.04095                    0.0"/>
        <axis xyz="0 1 0"/>
        <dynamics damping="0.0" friction="0.0"/>
    </joint>
    <!-- Xacro:Properties -->
    <!-- [m] -->
    <!-- [Nm] -->
    <link name="RH_SHANK">
        <visual>
            <origin rpy="0 0 -3.14159265359" xyz="0 0 0"/>
            <geometry>
                <mesh filename="anymal_shank_l.dae" scale="0.001 0.001     0.001"/>
            </geometry>
            <material name="anymal_material"/>
        </visual>
        <inertial>
            <origin rpy="0 0 0" xyz="-0.029 0.004 0.001"/>
            <mass value="0.21"/>
            <inertia ixx="0.0037693717909" ixy="-7.7334500762e-05" ixz="0.000152069372983" iyy="0.00400446467635"
                     iyz="0.0003218356083" izz="0.000418471691904"/>
        </inertial>
    </link>
    <!-- Shank joint -->
    <joint name="RH_KFE" type="revolute">
        <parent link="RH_THIGH"/>
        <child link="RH_SHANK"/>
        <origin xyz="-0.0 -0.109 -0.25"/>
        <axis xyz="0 1 0"/>
        <dynamics damping="0.0" friction="0.0"/>
    </joint>

    <!-- Xacro:Properties -->
    <!-- [m] -->
    <!-- Shank to Adapter joint -->
    <joint name="RH_SHANK_TO_ADAPTER" type="fixed">
        <parent link="RH_SHANK"/>
        <child link="RH_ADAPTER"/>
        <origin rpy="-0.0 -0.0 0.0" xyz="-0.1 0.02 0.0"/>
    </joint>

    <!-- Adapter link -->
    <link name="RH_ADAPTER">
        <visual>
            <origin rpy="0 0 0.0" xyz="0 0 -0.0325"/>
            <geometry>
                <mesh filename="anymal_adapter.dae" scale="0.001 0.001     0.001"/>
            </geometry>
            <material name="anymal_material"/>
        </visual>

        <collision>
            <origin rpy="0 0 0" xyz="0 0 -0.0"/>
            <geometry>
                <box size="0.045 0.045 0.065"/>
            </geometry>
            <material name="anymal_material"/>
        </collision>

        <collision>
            <origin rpy="0 0 0" xyz="0 0 -0.145"/>
            <geometry>
                <cylinder length="0.26" radius="0.015"/>
            </geometry>
            <material name="anymal_material"/>
        </collision>
    </link>
    <!-- Adapter to Foot joint -->

    <joint name="RH_ADAPTER_TO_FOOT" type="fixed">
        <parent link="RH_ADAPTER"/>
        <child link="RH_FOOT"/>
        <origin rpy="-0.0 -0.0 0.0" xyz="0.0 0.0 -0.28625"/>
    </joint>

    <!-- Foot link -->
    <link name="RH_FOOT">
        <visual>
            <origin xyz="0 0 0.03"/>
            <geometry>
                <mesh filename="anymal_bota.dae" scale="0.001 0.001     0.001"/>
            </geometry>
        </visual>
        <collision>
            <origin xyz="0 0 0"/>
            <geometry>
                <sphere radius="0.032"/>
            </geometry>
        </collision>
    </link>

    <!-- Gazebo customization -->
    <gazebo reference="RH_FOOT">
        <kp>1000000.0</kp>
        <kd>100.0</kd>
        <mu1>0.8</mu1>
        <mu2>0.8</mu2>
    </gazebo>
</robot>
